<?xml version="1.0"?>
<robot xmlns:xacro="http://www.ros.org/wiki/xacro" name="dds_robot">
  <material name="blue">
    <color rgba="${0/255} ${0/255} ${255/255} 0.1" />
  </material>
  <material name="white">
    <color rgba="${255/255} ${255/255} ${255/255} 0.1" />
  </material>
  <material name="orange">
    <color rgba="${255/255} ${108/255} ${10/255} 0.1" />
  </material>

  <material name="red">
    <color rgba="1 0 0 0.1" />
  </material>

  <link name="world"></link>


  <link name="base_link">
    <visual>
      <origin xyz="0 0 2" rpy="0 0 0" />
      <geometry>
        <box size="2 2 4"></box>
      </geometry>
      <material name="blue" />
    </visual>
    <collision>
      <origin xyz="0 0 2" rpy="0 0 0" />
      <geometry>
        <box size="2 2 4"></box>
      </geometry>
    </collision>
    <inertial>
      <origin xyz="0 0 2" rpy="0 0 0" />
      <mass value="12" />
      <inertia ixx="2.26" ixy="0.0" ixz="0.0" iyy="6.26" iyz="0.0" izz="8.5" />
    </inertial>

  </link>

  <joint name="base_joint" type="fixed">
    <origin xyz="4 4 0" rpy="0 0 0" />
    <parent link="world" />
    <child link="base_link" />
  </joint>

  <link name="pole_link">
    <visual>
      <origin xyz="0 0 2.5" rpy="0 0 0" />
      <geometry>
        <cylinder length="5" radius="0.1"></cylinder>
      </geometry>
      <material name="orange" />
    </visual>
    <collision>
      <origin xyz="0 0 2.5" rpy="0 0 0" />
      <geometry>
        <cylinder length="5" radius="0.1"></cylinder>
      </geometry>
    </collision>
    <inertial>
      <origin xyz="0 0 2.5" rpy="0 0 0" />
      <mass value="12" />
      <inertia ixx="2.26" ixy="0.0" ixz="0.0" iyy="6.26" iyz="0.0" izz="8.5" />
    </inertial>
  </link>

  <joint name="pole_joint" type="fixed">
    <origin xyz="0 0 4" rpy="0 0 0" />
    <parent link="base_link" />
    <child link="pole_link" />
  </joint>

  <!-- Lidar -->
  <link name="lidar_branch_link">
    <visual>
      <origin xyz="0.5 0 0" rpy="0 0 0" />
      <geometry>
        <box size="1 0.2 0.2" />
      </geometry>
      <material name="blue" />
    </visual>
    <collision>
      <origin xyz="0.5 0 0" rpy="0 0 0" />
      <geometry>
        <box size="1 0.2 0.2" />
      </geometry>
    </collision>
    <inertial>
      <origin xyz="0 0 0" rpy="0 0 0" />
      <mass value="12" />
      <inertia ixx="2.26" ixy="0.0" ixz="0.0" iyy="6.26" iyz="0.0" izz="8.5" />
    </inertial>
  </link>

  <joint name="lidar_branch_joint" type="fixed">
    <parent link="pole_link" />
    <child link="lidar_branch_link" />
    <origin xyz="0 0 4" rpy="0 0 0" />
  </joint>

  <link name="lidar_pan_link">
    <visual>
      <origin xyz="0 0 0.1" rpy="0 0 0" />
      <geometry>
        <box size="1 1 0.2" />
      </geometry>
      <material name="blue" />
    </visual>
    <collision>
      <origin xyz="0 0 0.1" rpy="0 0 0" />
      <geometry>
        <box size="1 1 0.2" />
      </geometry>
    </collision>
    <inertial>
      <origin xyz="0 0 0.1" rpy="0 0 0" />
      <mass value="12" />
      <inertia ixx="2.26" ixy="0.0" ixz="0.0" iyy="6.26" iyz="0.0" izz="8.5" />
    </inertial>
  </link>


  <joint name="lidar_pan_joint" type="continuous">
    <parent link="lidar_branch_link" />
    <child link="lidar_pan_link" />
    <axis xyz="0 0 0.1" />
    <origin xyz="1 0.1 0.1" rpy="0 0 0" />
  </joint>

  <link name="laser_frame">
    <visual>
      <origin xyz="0 0 0.02" rpy="0 0 0" />
      <geometry>
        <cylinder radius="0.05" length="0.04" />
      </geometry>
      <material name="red" />
    </visual>
    <collision>
      <origin xyz="0 0 0.02" rpy="0 0 0" />
      <geometry>
        <cylinder radius="0.05" length="0.04" />
      </geometry>
    </collision>
    <inertial>
      <origin xyz="0 0 0.02" rpy="0 0 0" />
      <mass value="12" />
      <inertia ixx="2.26" ixy="0.0" ixz="0.0" iyy="6.26" iyz="0.0" izz="8.5" />
    </inertial>
  </link>

  <joint name="laser_joint" type="fixed">
    <parent link="lidar_pan_link" />
    <child link="laser_frame" />
    <origin xyz="0 0 0.4" rpy="0 0 0" />
  </joint>

  <!-- Camera -->
  <link name="camera_pan_link">
    <visual>
      <origin xyz="0 0 0.1" rpy="0 0 0" />
      <geometry>
        <box size="1 1 0.2" />
      </geometry>
      <material name="blue" />
    </visual>
    <collision>
      <origin xyz="0 0 0.1" rpy="0 0 0" />
      <geometry>
        <box size="1 1 0.2" />
      </geometry>
    </collision>
    <inertial>
      <origin xyz="0 0 0.1" rpy="0 0 0" />
      <mass value="12" />
      <inertia ixx="2.26" ixy="0.0" ixz="0.0" iyy="6.26" iyz="0.0" izz="8.5" />
    </inertial>
  </link>


  <joint name="camera_pan_joint" type="continuous">
    <parent link="pole_link" />
    <child link="camera_pan_link" />
    <axis xyz="0 0 1" />
    <origin xyz="0 0 5" rpy="0 0 0" />
  </joint>

  <link name="camera_link">
    <visual>
      <origin xyz="0 0 0" rpy="0 0 0" />
      <geometry>
        <box size="0.12 0.15 0.15" />
      </geometry>
      <material name="white" />
    </visual>
    <collision>
      <origin xyz="0 0 0" rpy="0 0 0" />
      <geometry>
        <box size="0.12 0.15 0.15" />
      </geometry>
    </collision>
    <inertial>
      <origin xyz="0 0 0" rpy="0 0 0" />
      <mass value="12" />
      <inertia ixx="2.26" ixy="0.0" ixz="0.0" iyy="6.26" iyz="0.0" izz="8.5" />
    </inertial>
  </link>

  <joint name="camera_joint" type="fixed">
    <parent link="camera_pan_link" />
    <child link="camera_link" />
    <origin xyz="0 0 0.275" rpy="0 0 0" />
  </joint>

  <!-- <xacro:include filename="dds_gazebo.xacro" /> -->
  <gazebo reference="base_link">
    <material>Gazebo/Green</material>
  </gazebo>

  <gazebo reference="pole_link">
    <material>Gazebo/Green</material>
  </gazebo>
  <gazebo reference="camera_pan_link">
    <material>Gazebo/Blue</material>
  </gazebo>
  <gazebo reference="camera_link">
    <material>Gazebo/White</material>
  </gazebo>

  <gazebo>
    <plugin name="gazebo_ros_joint_state_publisher"
      filename="libgazebo_ros_joint_state_publisher.so">
      <update_rate>20</update_rate>
      <joint_name>camera_pan_joint</joint_name>
    </plugin>
  </gazebo>

  <gazebo>
    <plugin name="gazebo_ros_joint_pose_trajectory"
      filename="libgazebo_ros_joint_pose_trajectory.so">
      <update_rate>2</update_rate>
    </plugin>
  </gazebo>


  <joint name="camera_optical_joint" type="fixed">
    <origin xyz="0 0 0" rpy="-1.571 0 -1.571" />
    <parent link="camera_link" />
    <child link="camera_link_optical" />
  </joint>

  <link name="camera_link_optical"></link>

  <gazebo reference="camera_link">
    <sensor type="camera" name="my_camera">
      <update_rate>20</update_rate>
      <visualize>true</visualize>
      <camera name="cam">
        <horizontal_fov>1.3962634</horizontal_fov>
        <image>
          <width>640</width>
          <height>480</height>
          <format>R8B8G8</format>
        </image>
        <clip>
          <near>0.02</near>
          <far>300</far>
        </clip>
        <noise>
          <type>gaussian</type>
          <mean>0.0</mean>
          <stddev>0.007</stddev>
        </noise>
      </camera>
      <plugin name="camera_controller" filename="libgazebo_ros_camera.so">
        <frame_name>camera_link_optical</frame_name>
        <min_depth>0.1</min_depth>
        <max_depth>500</max_depth>
      </plugin>
    </sensor>

  </gazebo>

  <gazebo reference="laser_frame">
    <material>Gazebo/Red</material>

    <sensor name="laser" type="ray">
      <pose> 0 0 0 0 0 0 </pose>
      <visualize>true</visualize>
      <update_rate>10</update_rate>
      <ray>
        <scan>
          <horizontal>
            <samples>360</samples>
            <min_angle>-3.14</min_angle>
            <max_angle>3.14</max_angle>
          </horizontal>
          <!-- <vertical>
            <samples>360</samples>
            <min_angle>-3.14</min_angle>
            <max_angle>3.14</max_angle>
          </vertical> -->
        </scan>
        <range>
          <min>0.3</min>
          <max>12</max>
        </range>
      </ray>
      <plugin name="laser_controller" filename="libgazebo_ros_ray_sensor.so">
        <ros>
          <argument>~/out:=scan</argument>
        </ros>
        <output_type>sensor_msgs/LaserScan</output_type>
        <frame_name>laser_frame</frame_name>
      </plugin>
    </sensor>
  </gazebo>

</robot>